<mujoco>

    <!-- Front left leg type 3 -->
    <!-- IMPORTANT MODEL PARAMETERS
        'lr0':0.02678, 'rp': 0.008, 'd1': 0.0128, 'l1': 0.03, 
        'l2': 0.0084, 'l3': 0.045, 'l4': 0.025,'theta3':110*np.pi/180
    -->

        <body pos="0 0.0055 0">
            <geom name="main_box_rl" mass=".040" type="box" size=".0091 .014 .014" rgba="0 .9 0 1"/>
            
            <!-- Extension with slider for jumping -->
            <!-- joint name="rail" type="slide" axis="0 0 1"/ -->
            <!-- joint name="rail" type="slide" axis="0 0 1" damping="0.01" frictionloss="0.01" pos="0 -0.3325 0"/-->
            <body name ="main_leg_rl" pos="0.0136 -0.0055 -0.0085">

                <joint name="m1_rl" pos="0 0 0" type="hinge" axis="1 0 0" damping="0.01" armature="0.00065" limited="true" range="-90 90" ref="0"/>
                <geom name="leg1_rl" mass="0.001" type="capsule" fromto="0 0 0 0 0 -0.03" size="0.0024"/>
                <site name="router_hip_rl" pos="0 0 0" size="0.002" rgba=".1 .1 .8 0.5"/>
                <site name="knee_start_rl" pos="0 0 -0.023" size="0.002" rgba=".1 .1 .8 0.5"/>
                <body name="lower_leg_rl" pos="0 0 -0.03">
                    <joint name="knee1_rl" pos="0 0 0" type="hinge" axis="1 0 0" damping="0.005" armature="0.000065" limited="true" range="-80 80"/>
                    <geom name="leg2_rl" type="capsule" mass="0.0015" fromto="0 0 0 0 0.045 0" size="0.0015" rgba=".8 .1 .1 1"/>
                    <site name="m2_pickup_rl" pos="0 0.0084 0" size="0.002" rgba=".1 .1 .8 0.5"/>
                    <site name="knee_pickup_rl" pos="0 0.045 0" size="0.002" rgba=".1 .1 .8 0.5"/>
                    <body name="ankle_rl" pos="0 .045 0">
                        <joint name="ankle_rl" pos="0 0 0" type="hinge" axis="1 0 0" damping="0.005" stiffness="0.1" armature="0.000065" limited="true" range="-90 90"/>
                        <geom name="foot_rl" type="capsule" mass="0.001" fromto="0 0 0 0 0 -0.023" size="0.0013" rgba=".8 .1 .1 1" friction="1.4 0.005 0.0001" />
                    </body>
                </body>
            </body>

            <site name="x1_rl" pos="0.0136 0.0055 0.0043" size="0.002" rgba=".1 .1 .8 0.2"/>
            <body name="servo2_rl" pos="0.0136 -0.0055 0.0043">
                <geom name="motor2_rl" type="cylinder" mass="0.002" fromto="-0.003 0 0 0.003 0 0" size="0.008" rgba=".8 .1 .1 1" />
                <joint name="m2_rl" pos="0 0 0" type="hinge" axis="1 0 0" armature="0.00065" damping="0.01" limited="true" range="-37 37" ref="0"/>
                
                <site name="s1_rl" pos="0.0 0.0 0.009" size="0.002" rgba=".1 .1 .8 0.5"/>
            </body>
        </body>
</mujoco>