<mujoco>

    <!-- Front left leg type 3 -->
    <!-- IMPORTANT MODEL PARAMETERS
        'lr0':0.02678, 'rp': 0.008, 'd1': 0.0128, 'l1': 0.0317, 
        'l2': 0.01, 'l3': 0.0305, 'l4': 0.0205,'theta3':73*np.pi/180
    -->

        <body pos="0 0 0">
            <geom name="main_box_rr" mass=".015" type="box" pos="-0.011 0.008 0" size=".004 .014 .014" rgba="0.7 0.7 0.7 1"/>
            
            <!-- Extension with slider for jumping -->
            <!-- joint name="rail" type="slide" axis="0 0 1"/ -->
            <!-- joint name="rail" type="slide" axis="0 0 1" damping="0.01" frictionloss="0.01" pos="0 -0.3325 0"/-->
            <body name ="main_leg_rr" pos="-0.025 0.0025 -0.0064">

                <joint name="m1_rr" pos="0 0 0" type="hinge" axis="1 0 0" damping="0.01" armature="0.00065" limited="true" range="-90 90" ref="0"/>
                <geom name="leg1_rr" mass="0.001" type="capsule" fromto="0 0 0 0 0 -0.0317" size="0.0024" rgba=".95 .95 .95 1"/>

                <site name="router_hip_rr" pos="0 0 0" size="0.002" rgba="1 .4 .4 0.3"/>
                <body name="lower_leg_rr" pos="0 0 -0.0317">
                    <joint name="knee1_rr" pos="0 0 0" type="hinge" axis="1 0 0" stiffness="0.19" damping="0.005" armature="0.000065" limited="true" range="-90 90" ref="15"/>
                    <geom name="leg2_rr" type="capsule" mass="0.0015" fromto="0 0 0 0 0.0305 0" size="0.009" rgba="1 .4 .4 1"/>
                    <site name="m2_pickup_rr" pos="0 0.02 0" size="0.002" rgba="1 .4 .4 0.3"/>

                    <body name="foot_rr" pos="0 0.0305 0">
                        <joint name="ankle_rr" pos="0 0 0" type="hinge" axis="1 0 0" stiffness="0.1" damping="0.005" armature="0.000065" limited="true" range="-70 70" ref="-17"/>

                        <geom name="ankle_rr" type="capsule" mass="0.001" fromto="0 0 0 0 0 -0.0205" size="0.001" rgba="1 .4 .4 1"/>
                        <!--geom name="foot_placement_rr" type="sphere" pos="0 0 -0.0205" size="0.0025" rgba=".8 .1 .1 1"/-->
                        <geom name="foot_placement_rr2" type="capsule" fromto="-0.0035 0 -0.0205 0.0035 0 -0.0205" friction="1.4 0.005 0.0001" size="0.002" rgba="1 .4 .4 1"/> 
                        <site name="foot_s_rr" pos="0 0 -0.0205" size="0.004" rgba="1 .4 .4 0.3"/>
                    </body>
                </body>
            </body>

            <site name="x1_rr" pos="-0.025 0.02 0.0064" size="0.002" rgba="1 .4 .4 0.3"/>
            <body name="servo2_rr" pos="-0.025 0.0025 0.0064">
                <geom name="motor2_rr" type="cylinder" mass="0.002" fromto="-0.003 0 0 0.003 0 0" size="0.008" rgba="1 .4 .4 1"/>
                <joint name="m2_rr" pos="0 0 0" type="hinge" axis="1 0 0" armature="0.00065" damping="0.01" limited="true" range="-180 180" ref="0"/>
                
                <site name="s1_rr" pos="0.0 0.0 0.009" size="0.002" rgba="1 .4 .4 0.3"/>
            </body>
        </body>
</mujoco>