<mujoco>
    <!-- Front right leg type 3 -->
    <!-- IMPORTANT MODEL PARAMETERS
        'lr0':0.033, 'rp': 0.008, 'd1': 0.0128, 'l1': 0.025, 
        'l2': 0.018, 'l3': 0.028, 'l4': 0.015,'theta3':np.pi/10
    -->
        <body pos="0 0.0055 0.0">
            <geom name="servo_box_fr" mass=".04" type="box" size=".0091 .014 .014" rgba="0 .9 0 1"/>
            
            <body name ="main_leg_fr" pos="-0.0136 -0.0055 -0.0085">
                <joint name="m1_fr" pos="0 0 0" type="hinge" axis="1 0 0" damping="0.01" armature="0.00065" limited="true" range="-180 180" ref="90"/>
                <geom name="leg1_fr" mass="0.001" type="capsule" fromto="0 0 0 0 0.025 0" size="0.0032"/>
                <site name="router_shoulder_fr" pos="0 0 0" size="0.002" rgba=".1 .1 .8 .5"/>
                <site name="knee_start_fr" pos="0 0.0068 0" size="0.002" rgba=".1 .1 .8 .5"/>
                <body name="lower_leg_fr" pos="0 0.025 0">
                    <joint name="knee1_fr" pos="0 0 0" type="hinge" axis="1 0 0" damping="0.005" armature="0.000065" limited="true" range="-70 70" />
                    <geom name="leg2_fr" type="capsule" mass="0.0015" fromto="0 0 0 0 0 -0.028" size="0.002" rgba=".8 .1 .1 1"/>
                    <geom name="ankle_fr" type="capsule" mass="0.001" fromto="0 0 -0.028 0 -0.002 -0.040" friction="1.4 0.005 0.0001" size="0.002" rgba=".8 .1 .1 1"/>
                    <site name="m2_pickup_fr" pos="0 0 -0.018" size="0.002" rgba=".1 .1 .8 0.5"/>
                    <site name="knee_pickup_fr" pos="0 0 -0.028" size="0.002" rgba=".1 .1 .8 0.5"/>
                    <site name="ankle_start_fr" pos="0 0 -0.010" size="0.002" rgba=".1 .1 .8 0.5"/>
                </body>
            </body>

            <site name="x1_fr" pos="-0.0136 -0.02 0.00" size="0.002" rgba=".1 .1 .8 0.2"/>
            <body name="servo2_fr" pos="-0.0136 -0.0055 0.0043">
                <geom name="motor2_fr" type="cylinder" mass="0.002" fromto="-0.003 0 0 0.003 0 0" size="0.008" rgba=".8 .1 .1 1" />
                <joint name="m2_fr" pos="0 0 0" type="hinge" axis="1 0 0" armature="0.00065" damping="0.01" limited="true" range="-180 180"/>
                
                <site name="s1_fr" pos="0.0 0 0.009" size="0.002" rgba=".1 .1 .8 0.5"/>
            </body>
        </body>
</mujoco>