<mujoco>
    <!-- Front left leg type 3 -->
    <!-- IMPORTANT MODEL PARAMETERS
        'lr0':0.033, 'rp': 0.008, 'd1': 0.0128, 'l1': 0.0295, 
        'l2': 0.0145, 'l3': 0.0225, 'l4': 0.0145,'theta3':23*np.pi/180
    -->

        <body pos="0 0 0">
            <geom name="servo_box_fr" mass=".015" type="box" pos="-0.011 0.008 0" size=".0097 .014 .014" rgba="0.7 0.7 0.7 1"/>

            <body name ="main_leg_fr" pos="-0.025 0.0025 -0.0064">

                <joint name="m1_fr" pos="0 0 0" type="hinge" axis="1 0 0" damping="0.01" armature="0.00065" limited="true" range="-180 180" ref="0"/>
                <geom name="leg1_fr" mass="0.001" type="capsule" fromto="0 0 0 0 0 -0.0295 " size="0.0032" rgba=".95 .95 .95 1"/>

                <site name="router_shoulder_fr" pos="0 0 0" size="0.002" rgba="1 .4 .4 0.3"/>
                <site name="knee_start_fr" pos="0 0 -0.0068" size="0.002" rgba="1 .4 .4 0.3"/>
                <body name="lower_leg_fr" pos="0 0 -0.0295">
                    <joint name="knee1_fr" pos="0 0 0" type="hinge" axis="1 0 0" damping="0.005" stiffness="0.135" armature="0.000065" limited="true" range="-90 20" ref="50"/>
                    <geom name="knee_fr" type="sphere" mass="0.0005" size="0.0075" rgba="1 .4 .4 1"/>
                    <geom name="leg2_fr" type="capsule" mass="0.0010" fromto="0 0 0 0 0 -0.0225" size="0.002" rgba="1 .4 .4 1"/>
                    <site name="m2_pickup_fr" pos="0 0 -0.0145" size="0.002" rgba="1 .4 .4 0.3"/>

                    <body name="foot_fr" pos="0 0 -0.0225">
                        <joint name="ankle_fr" pos="0 0 0" type="hinge" axis="1 0 0" stiffness="0.1" damping="0.005" armature="0.000065" limited="true" range="-70 70" ref="23"/>
                        <geom name="ankle_fr" type="capsule" mass="0.001" fromto="0 0 0 0 0 -0.0145" size="0.0015" rgba="1 .4 .4 1"/>
                        <!--geom name="foot_placement_fr" type="sphere" pos="0 0 -0.0145" size="0.0025" rgba=".8 .1 .1 1"/-->
                        <geom name="foot_placement_fr2" type="capsule" fromto="-0.0035 0 -0.0145 0.0035 0 -0.0145" friction="1.4 0.005 0.0001" size="0.002" rgba="1 .4 .4 1"/> 

                        <site name="foot_s_fr" pos="0 0 -0.0145" size="0.004" rgba="1 .4 .4 0.3"/>
                    </body>
                </body>
            </body>

            <site name="x1_fr" pos="-0.025 -0.02 0.00" size="0.002" rgba="1 .4 .4 0.3"/>
            <body name="servo2_fr" pos="-0.025 0.0025 0.0064">
                <geom name="motor2_fr" type="cylinder" mass="0.002" fromto="-0.003 0 0 0.003 0 0" size="0.008" rgba="1 .4 .4 1"/>
                <joint name="m2_fr" pos="0 0 0" type="hinge" axis="1 0 0" armature="0.00065" damping="0.01" limited="true" range="-180 180"/>

                <site name="s1_fr" pos="0.0 0 0.009" size="0.002" rgba="1 .4 .4 0.3"/>
            </body>
        </body>
</mujoco>